Workbook

Sheet Config_Setup
B2: ⚙ CONFIG SETUP | F2: 📋 LEDGER | J2: ∑ ENGINE | N2: ◉ DASHBOARD
B5: CONFIGURATION SETUP
B7: ENTITY TYPES | N7: ◀ VALIDATION REFERENCE LISTS (do not edit) ▶
B8: Entity ID | C8: Entity Name | N8: Category Names | O8: Sub-Category Names
B9: ENT-01 | C9: Business | N9: Business Income | O9: Acquisition
B10: ENT-02 | C10: Personal | N10: Business Operating Expense | O10: Service Fees
B11: ENT-03 | C11: Transfer | N11: Owner's Draw | O11: Retainer
N12: Personal Income | O12: SaaS Subscriptions
B13: TRANSACTION TYPES | N13: Survival Expenses | O13: Payroll
B14: Tx Type | N14: Discretionary Expenses | O14: Rent (Office)
B15: Inflow | N15: Savings | O15: Marketing
B16: Outflow | O16: Travel & Entertainment
O17: Owner's Draw
B18: STATUS VALUES | O18: Active Salary
B19: Status | O19: Other Personal Income
B20: Cleared | O20: Rent (Home)
B21: Pending | O21: Utilities
O22: Groceries
E23: CATEGORY & SUB-CATEGORY TAXONOMY | O23: Dining Out
E24: Category Group | F24: Category Name | G24: Sub-Category Name | O24: Shopping
E25: Revenue | F25: Business Income | G25: Acquisition | O25: Luxury
E26: Revenue | F26: Business Income | G26: Service Fees | O26: Entertainment
E27: Revenue | F27: Business Income | G27: Retainer | O27: Emergency Fund
E28: Expense | F28: Business Operating Expense | G28: SaaS Subscriptions | O28: Investment
E29: Expense | F29: Business Operating Expense | G29: Payroll
E30: Expense | F30: Business Operating Expense | G30: Rent (Office)
E31: Expense | F31: Business Operating Expense | G31: Marketing
E32: Expense | F32: Business Operating Expense | G32: Travel & Entertainment
E33: Expense | F33: Owner's Draw | G33: Owner's Draw
E34: Revenue | F34: Personal Income | G34: Active Salary
E35: Revenue | F35: Personal Income | G35: Other Personal Income
E36: Expense | F36: Survival Expenses | G36: Rent (Home)
E37: Expense | F37: Survival Expenses | G37: Utilities
E38: Expense | F38: Survival Expenses | G38: Groceries
E39: Expense | F39: Discretionary Expenses | G39: Dining Out
E40: Expense | F40: Discretionary Expenses | G40: Shopping
... E44: Savings | F44: Savings | G44: Investment
B47: BUDGET & ALERT THRESHOLDS
B48: Budget Item | C48: Weekly Limit | D48: Monthly Limit | E48: Alert %
B49: Personal Discretionary | C49: 300 | D49: 1200 | E49: 0.85
...

Sheet Data_Transactions
B2: ⚙ CONFIG SETUP | F2: 📋 LEDGER | J2: ∑ ENGINE | N2: ◉ DASHBOARD
B5: TRANSACTION LEDGER
B6: Log every business and personal cash movement. Owner resolves Pending items during weekly check-in.
B7: Tx ID | C7: Date | D7: Entity | E7: Type | F7: Category | G7: Sub-Category | H7: Amount | I7: Description | J7: Status | K7: Acct. Flag | L7: Admin Notes
B8: =IF(C8="","","TX-"&TEXT(YEAR(C8),"0000")&"-"&TEXT(ROW()-7,"0000")) -> TX-2026-0001 | C8: 46175 | D8: Business | E8: Inflow | F8: Business Income | G8: Acquisition | H8: 5000 | I8: Client payment — ABC Corp | J8: Cleared | K8: =IF(J8="Pending",TRUE(),FALSE()) -> FALSE
B9: =IF(C9="","","TX-"&TEXT(YEAR(C9),"0000")&"-"&TEXT(ROW()-7,"0000")) -> TX-2026-0002 | C9: 46176 | D9: Business | E9: Outflow | F9: Business Operating Expense | G9: SaaS Subscriptions | H9: 150 | I9: Slack annual subscription | J9: Cleared | K9: =IF(J9="Pending",TRUE(),FALSE()) -> FALSE
B10: =IF(C10="","","TX-"&TEXT(YEAR(C10),"0000")&"-"&TEXT(ROW()-7,"0000")) -> TX-2026-0003 | C10: 46177 | D10: Business | E10: Outflow | F10: Business Operating Expense | G10: Marketing | H10: 800 | I10: Google Ads — June campaign | J10: Cleared | K10: =IF(J10="Pending",TRUE(),FALSE()) -> FALSE
B11: =IF(C11="","","TX-"&TEXT(YEAR(C11),"0000")&"-"&TEXT(ROW()-7,"0000")) -> TX-2026-0004 | C11: 46178 | D11: Business | E11: Outflow | F11: Owner's Draw | G11: Owner's Draw | H11: 3000 | I11: Monthly owner draw | J11: Cleared | K11: =IF(J11="Pending",TRUE(),FALSE()) -> FALSE
B12: =IF(C12="","","TX-"&TEXT(YEAR(C12),"0000")&"-"&TEXT(ROW()-7,"0000")) -> TX-2026-0005 | C12: 46178 | D12: Personal | E12: Inflow | F12: Personal Income | G12: Active Salary | H12: 3000 | I12: Owner draw received — personal account | J12: Cleared | K12: =IF(J12="Pending",TRUE(),FALSE()) -> FALSE
B13: =IF(C13="","","TX-"&TEXT(YEAR(C13),"0000")&"-"&TEXT(ROW()-7,"0000")) -> TX-2026-0006 | C13: 46176 | D13: Personal | E13: Outflow | F13: Survival Expenses | G13: Rent (Home) | H13: 1500 | I13: June monthly rent | J13: Cleared | K13: =IF(J13="Pending",TRUE(),FALSE()) -> FALSE
B14: =IF(C14="","","TX-"&TEXT(YEAR(C14),"0000")&"-"&TEXT(ROW()-7,"0000")) -> TX-2026-0007 | C14: 46177 | D14: Personal | E14: Outflow | F14: Discretionary Expenses | G14: Dining Out | H14: 85 | I14: Dinner — The Capital Grille | J14: Cleared | K14: =IF(J14="Pending",TRUE(),FALSE()) -> FALSE
B15: =IF(C15="","","TX-"&TEXT(YEAR(C15),"0000")&"-"&TEXT(ROW()-7,"0000")) -> TX-2026-0008 | C15: 46170 | D15: Business | E15: Inflow | F15: Business Income | G15: Service Fees | H15: 2500 | I15: Retainer — XYZ Consulting Ltd | J15: Cleared | K15: =IF(J15="Pending",TRUE(),FALSE()) -> FALSE
B16: =IF(C16="","","TX-"&TEXT(YEAR(C16),"0000")&"-"&TEXT(ROW()-7,"0000")) -> TX-2026-0009 | C16: 46171 | D16: Business | E16: Outflow | F16: Business Operating Expense | G16: Payroll | H16: 4000 | I16: Contractor payment — Dev team | J16: Cleared | K16: =IF(J16="Pending",TRUE(),FALSE()) -> FALSE
B17: =IF(C17="","","TX-"&TEXT(YEAR(C17),"0000")&"-"&TEXT(ROW()-7,"0000")) -> TX-2026-0010 | C17: 46168 | D17: Personal | E17: Outflow | F17: Survival Expenses | G17: Groceries | H17: 200 | I17: Weekly groceries — Whole Foods | J17: Cleared | K17: =IF(J17="Pending",TRUE(),FALSE()) -> FALSE
B18: =IF(C18="","","TX-"&TEXT(YEAR(C18),"0000")&"-"&TEXT(ROW()-7,"0000")) -> TX-2026-0011 | C18: 46169 | D18: Personal | E18: Outflow | F18: Discretionary Expenses | G18: Shopping | H18: 150 | I18: Amazon order — home office supplies | J18: Cleared | K18: =IF(J18="Pending",TRUE(),FALSE()) -> FALSE
B19: =IF(C19="","","TX-"&TEXT(YEAR(C19),"0000")&"-"&TEXT(ROW()-7,"0000")) -> TX-2026-0012 | C19: 46179 | D19: Personal | E19: Outflow | F19: Discretionary Expenses | G19: Entertainment | H19: 45 | I19: Netflix annual subscription | J19: Pending | K19: =IF(J19="Pending",TRUE(),FALSE()) -> TRUE
B20: =IF(C20="","","TX-"&TEXT(YEAR(C20),"0000")&"-"&TEXT(ROW()-7,"0000")) | K20: =IF(J20="Pending",TRUE(),FALSE()) -> FALSE
B21: =IF(C21="","","TX-"&TEXT(YEAR(C21),"0000")&"-"&TEXT(ROW()-7,"0000")) | K21: =IF(J21="Pending",TRUE(),FALSE()) -> FALSE
B22: =IF(C22="","","TX-"&TEXT(YEAR(C22),"0000")&"-"&TEXT(ROW()-7,"0000")) | K22: =IF(J22="Pending",TRUE(),FALSE()) -> FALSE
B23: =IF(C23="","","TX-"&TEXT(YEAR(C23),"0000")&"-"&TEXT(ROW()-7,"0000")) | K23: =IF(J23="Pending",TRUE(),FALSE()) -> FALSE
B24: =IF(C24="","","TX-"&TEXT(YEAR(C24),"0000")&"-"&TEXT(ROW()-7,"0000")) | K24: =IF(J24="Pending",TRUE(),FALSE()) -> FALSE
B25: =IF(C25="","","TX-"&TEXT(YEAR(C25),"0000")&"-"&TEXT(ROW()-7,"0000")) | K25: =IF(J25="Pending",TRUE(),FALSE()) -> FALSE
B26: =IF(C26="","","TX-"&TEXT(YEAR(C26),"0000")&"-"&TEXT(ROW()-7,"0000")) | K26: =IF(J26="Pending",TRUE(),FALSE()) -> FALSE
B27: =IF(C27="","","TX-"&TEXT(YEAR(C27),"0000")&"-"&TEXT(ROW()-7,"0000")) | K27: =IF(J27="Pending",TRUE(),FALSE()) -> FALSE
B28: =IF(C28="","","TX-"&TEXT(YEAR(C28),"0000")&"-"&TEXT(ROW()-7,"0000")) | K28: =IF(J28="Pending",TRUE(),FALSE()) -> FALSE
B29: =IF(C29="","","TX-"&TEXT(YEAR(C29),"0000")&"-"&TEXT(ROW()-7,"0000")) | K29: =IF(J29="Pending",TRUE(),FALSE()) -> FALSE
B30: =IF(C30="","","TX-"&TEXT(YEAR(C30),"0000")&"-"&TEXT(ROW()-7,"0000")) | K30: =IF(J30="Pending",TRUE(),FALSE()) -> FALSE
B31: =IF(C31="","","TX-"&TEXT(YEAR(C31),"0000")&"-"&TEXT(ROW()-7,"0000")) | K31: =IF(J31="Pending",TRUE(),FALSE()) -> FALSE
... B107: =IF(C107="","","TX-"&TEXT(YEAR(C107),"0000")&"-"&TEXT(ROW()-7,"0000")) | K107: =IF(J107="Pending",TRUE(),FALSE()) -> FALSE
B108: ↓ Append new rows here — copy row format from above as needed

Sheet Calc_Engine
B2: ⚙ CONFIG SETUP | F2: 📋 LEDGER | J2: ∑ ENGINE | N2: ◉ DASHBOARD
B5: CALCULATION ENGINE
B6: Protected — do not edit. All values auto-calculated from Data_Transactions ledger.
B7: Period Start | C7: Period End | D7: Biz Income | E7: Biz OpEx | F7: Owner's Draw | G7: Biz Net CF | H7: Pers Income | I7: Pers Survival | J7: Pers Discretion | K7: Pers Net CF | L7: Cumul Biz Cash | M7: Monthly Burn Rate | N7: Runway (Mo.) | O7: Draw Recip. Check
B8: =TODAY()-WEEKDAY(TODAY(),2)+1-77 -> 46097 | C8: =B8+6 -> 46103 | D8: =SUMIFS(Data_Transactions!$H$8:$H$507,Data_Transactions!$D$8:$D$507,"Business",Data_Transactions!$E$8:$E$507,"Inflow",Data_Transactions!$C$8:$C$507,">="&B8,Data_Transactions!$C$8:$C$507,"<="&C8) -> 0 | E8: =SUMIFS(Data_Transactions!$H$8:$H$507,Data_Transactions!$D$8:$D$507,"Business",Data_Transactions!$E$8:$E$507,"Outflow",Data_Transactions!$F$8:$F$507,"Business Operating Expense",Data_Transactions!$C$8:$C$507,">="&B8,Data_Transactions!$C$8:$C$507,"<="&C8) -> 0 | F8: =SUMIFS(Data_Transactions!$H$8:$H$507,Data_Transactions!$D$8:$D$507,"Business",Data_Transactions!$E$8:$E$507,"Outflow",Data_Transactions!$F$8:$F$507,"Owner's Draw",Data_Transactions!$C$8:$C$507,">="&B8,Data_Transactions!$C$8:$C$507,"<="&C8) -> 0 | G8: =D8-E8-F8 -> 0 | H8: =SUMIFS(Data_Transactions!$H$8:$H$507,Data_Transactions!$D$8:$D$507,"Personal",Data_Transactions!$E$8:$E$507,"Inflow",Data_Transactions!$C$8:$C$507,">="&B8,Data_Transactions!$C$8:$C$507,"<="&C8) -> 0 | I8: =SUMIFS(Data_Transactions!$H$8:$H$507,Data_Transactions!$D$8:$D$507,"Personal",Data_Transactions!$E$8:$E$507,"Outflow",Data_Transactions!$F$8:$F$507,"Survival Expenses",Data_Transactions!$C$8:$C$507,">="&B8,Data_Transactions!$C$8:$C$507,"<="&C8) -> 0 | J8: =SUMIFS(Data_Transactions!$H$8:$H$507,Data_Transactions!$D$8:$D$507,"Personal",Data_Transactions!$E$8:$E$507,"Outflow",Data_Transactions!$F$8:$F$507,"Discretionary Expenses",Data_Transactions!$C$8:$C$507,">="&B8,Data_Transactions!$C$8:$C$507,"<="&C8) -> 0 | K8: =H8-I8-J8 -> 0 | L8: =IFERROR(Config_Setup!$C$56,0)+G8 -> 25000 | M8: =IFERROR(SUMIFS(Data_Transactions!$H$8:$H$507,Data_Transactions!$D$8:$D$507,"Business",Data_Transactions!$E$8:$E$507,"Outflow",Data_Transactions!$C$8:$C$507,">="&(C8-91),Data_Transactions!$C$8:$C$507,"<="&C8)/3,0) -> 0 | N8: =IFERROR(L8/M8,0) -> 0 | O8: =IF(F8=0,"N/A",IF(ABS(F8-(SUMIFS(Data_Transactions!$H$8:$H$507,Data_Transactions!$D$8:$D$507,"Personal",Data_Transactions!$E$8:$E$507,"Inflow",Data_Transactions!$G$8:$G$507,"Active Salary",Data_Transactions!$C$8:$C$507,">="&(B8-3),Data_Transactions!$C$8:$C$507,"<="&(C8+3))))>0.01,"⚠ MISMATCH","✓ OK")) -> N/A
B9: =TODAY()-WEEKDAY(TODAY(),2)+1-70 -> 46104 | C9: =B9+6 -> 46110 | D9: =SUMIFS(Data_Transactions!$H$8:$H$507,Data_Transactions!$D$8:$D$507,"Business",Data_Transactions!$E$8:$E$507,"Inflow",Data_Transactions!$C$8:$C$507,">="&B9,Data_Transactions!$C$8:$C$507,"<="&C9) -> 0 | E9: =SUMIFS(Data_Transactions!$H$8:$H$507,Data_Transactions!$D$8:$D$507,"Business",Data_Transactions!$E$8:$E$507,"Outflow",Data_Transactions!$F$8:$F$507,"Business Operating Expense",Data_Transactions!$C$8:$C$507,">="&B9,Data_Transactions!$C$8:$C$507,"<="&C9) -> 0 | F9: =SUMIFS(Data_Transactions!$H$8:$H$507,Data_Transactions!$D$8:$D$507,"Business",Data_Transactions!$E$8:$E$507,"Outflow",Data_Transactions!$F$8:$F$507,"Owner's Draw",Data_Transactions!$C$8:$C$507,">="&B9,Data_Transactions!$C$8:$C$507,"<="&C9) -> 0 | G9: =D9-E9-F9 -> 0 | H9: =SUMIFS(Data_Transactions!$H$8:$H$507,Data_Transactions!$D$8:$D$507,"Personal",Data_Transactions!$E$8:$E$507,"Inflow",Data_Transactions!$C$8:$C$507,">="&B9,Data_Transactions!$C$8:$C$507,"<="&C9) -> 0 | I9: =SUMIFS(Data_Transactions!$H$8:$H$507,Data_Transactions!$D$8:$D$507,"Personal",Data_Transactions!$E$8:$E$507,"Outflow",Data_Transactions!$F$8:$F$507,"Survival Expenses",Data_Transactions!$C$8:$C$507,">="&B9,Data_Transactions!$C$8:$C$507,"<="&C9) -> 0 | J9: =SUMIFS(Data_Transactions!$H$8:$H$507,Data_Transactions!$D$8:$D$507,"Personal",Data_Transactions!$E$8:$E$507,"Outflow",Data_Transactions!$F$8:$F$507,"Discretionary Expenses",Data_Transactions!$C$8:$C$507,">="&B9,Data_Transactions!$C$8:$C$507,"<="&C9) -> 0 | K9: =H9-I9-J9 -> 0 | L9: =L8+G9 -> 25000 | M9: =IFERROR(SUMIFS(Data_Transactions!$H$8:$H$507,Data_Transactions!$D$8:$D$507,"Business",Data_Transactions!$E$8:$E$507,"Outflow",Data_Transactions!$C$8:$C$507,">="&(C9-91),Data_Transactions!$C$8:$C$507,"<="&C9)/3,0) -> 0 | N9: =IFERROR(L9/M9,0) -> 0 | O9: =IF(F9=0,"N/A",IF(ABS(F9-(SUMIFS(Data_Transactions!$H$8:$H$507,Data_Transactions!$D$8:$D$507,"Personal",Data_Transactions!$E$8:$E$507,"Inflow",Data_Transactions!$G$8:$G$507,"Active Salary",Data_Transactions!$C$8:$C$507,">="&(B9-3),Data_Transactions!$C$8:$C$507,"<="&(C9+3))))>0.01,"⚠ MISMATCH","✓ OK")) -> N/A
B10: =TODAY()-WEEKDAY(TODAY(),2)+1-63 -> 46111 | C10: =B10+6 -> 46117 | D10: =SUMIFS(Data_Transactions!$H$8:$H$507,Data_Transactions!$D$8:$D$507,"Business",Data_Transactions!$E$8:$E$507,"Inflow",Data_Transactions!$C$8:$C$507,">="&B10,Data_Transactions!$C$8:$C$507,"<="&C10) -> 0 | E10: =SUMIFS(Data_Transactions!$H$8:$H$507,Data_Transactions!$D$8:$D$507,"Business",Data_Transactions!$E$8:$E$507,"Outflow",Data_Transactions!$F$8:$F$507,"Business Operating Expense",Data_Transactions!$C$8:$C$507,">="&B10,Data_Transactions!$C$8:$C$507,"<="&C10) -> 0 | F10: =SUMIFS(Data_Transactions!$H$8:$H$507,Data_Transactions!$D$8:$D$507,"Business",Data_Transactions!$E$8:$E$507,"Outflow",Data_Transactions!$F$8:$F$507,"Owner's Draw",Data_Transactions!$C$8:$C$507,">="&B10,Data_Transactions!$C$8:$C$507,"<="&C10) -> 0 | G10: =D10-E10-F10 -> 0 | H10: =SUMIFS(Data_Transactions!$H$8:$H$507,Data_Transactions!$D$8:$D$507,"Personal",Data_Transactions!$E$8:$E$507,"Inflow",Data_Transactions!$C$8:$C$507,">="&B10,Data_Transactions!$C$8:$C$507,"<="&C10) -> 0 | I10: =SUMIFS(Data_Transactions!$H$8:$H$507,Data_Transactions!$D$8:$D$507,"Personal",Data_Transactions!$E$8:$E$507,"Outflow",Data_Transactions!$F$8:$F$507,"Survival Expenses",Data_Transactions!$C$8:$C$507,">="&B10,Data_Transactions!$C$8:$C$507,"<="&C10) -> 0 | J10: =SUMIFS(Data_Transactions!$H$8:$H$507,Data_Transactions!$D$8:$D$507,"Personal",Data_Transactions!$E$8:$E$507,"Outflow",Data_Transactions!$F$8:$F$507,"Discretionary Expenses",Data_Transactions!$C$8:$C$507,">="&B10,Data_Transactions!$C$8:$C$507,"<="&C10) -> 0 | K10: =H10-I10-J10 -> 0 | L10: =L9+G10 -> 25000 | M10: =IFERROR(SUMIFS(Data_Transactions!$H$8:$H$507,Data_Transactions!$D$8:$D$507,"Business",Data_Transactions!$E$8:$E$507,"Outflow",Data_Transactions!$C$8:$C$507,">="&(C10-91),Data_Transactions!$C$8:$C$507,"<="&C10)/3,0) -> 0 | N10: =IFERROR(L10/M10,0) -> 0 | O10: =IF(F10=0,"N/A",IF(ABS(F10-(SUMIFS(Data_Transactions!$H$8:$H$507,Data_Transactions!$D$8:$D$507,"Personal",Data_Transactions!$E$8:$E$507,"Inflow",Data_Transactions!$G$8:$G$507,"Active Salary",Data_Transactions!$C$8:$C$507,">="&(B10-3),Data_Transactions!$C$8:$C$507,"<="&(C10+3))))>0.01,"⚠ MISMATCH","✓ OK")) -> N/A
B11: =TODAY()-WEEKDAY(TODAY(),2)+1-56 -> 46118 | C11: =B11+6 -> 46124 | D11: =SUMIFS(Data_Transactions!$H$8:$H$507,Data_Transactions!$D$8:$D$507,"Business",Data_Transactions!$E$8:$E$507,"Inflow",Data_Transactions!$C$8:$C$507,">="&B11,Data_Transactions!$C$8:$C$507,"<="&C11) -> 0 | E11: =SUMIFS(Data_Transactions!$H$8:$H$507,Data_Transactions!$D$8:$D$507,"Business",Data_Transactions!$E$8:$E$507,"Outflow",Data_Transactions!$F$8:$F$507,"Business Operating Expense",Data_Transactions!$C$8:$C$507,">="&B11,Data_Transactions!$C$8:$C$507,"<="&C11) -> 0 | F11: =SUMIFS(Data_Transactions!$H$8:$H$507,Data_Transactions!$D$8:$D$507,"Business",Data_Transactions!$E$8:$E$507,"Outflow",Data_Transactions!$F$8:$F$507,"Owner's Draw",Data_Transactions!$C$8:$C$507,">="&B11,Data_Transactions!$C$8:$C$507,"<="&C11) -> 0 | G11: =D11-E11-F11 -> 0 | H11: =SUMIFS(Data_Transactions!$H$8:$H$507,Data_Transactions!$D$8:$D$507,"Personal",Data_Transactions!$E$8:$E$507,"Inflow",Data_Transactions!$C$8:$C$507,">="&B11,Data_Transactions!$C$8:$C$507,"<="&C11) -> 0 | I11: =SUMIFS(Data_Transactions!$H$8:$H$507,Data_Transactions!$D$8:$D$507,"Personal",Data_Transactions!$E$8:$E$507,"Outflow",Data_Transactions!$F$8:$F$507,"Survival Expenses",Data_Transactions!$C$8:$C$507,">="&B11,Data_Transactions!$C$8:$C$507,"<="&C11) -> 0 | J11: =SUMIFS(Data_Transactions!$H$8:$H$507,Data_Transactions!$D$8:$D$507,"Personal",Data_Transactions!$E$8:$E$507,"Outflow",Data_Transactions!$F$8:$F$507,"Discretionary Expenses",Data_Transactions!$C$8:$C$507,">="&B11,Data_Transactions!$C$8:$C$507,"<="&C11) -> 0 | K11: =H11-I11-J11 -> 0 | L11: =L10+G11 -> 25000 | M11: =IFERROR(SUMIFS(Data_Transactions!$H$8:$H$507,Data_Transactions!$D$8:$D$507,"Business",Data_Transactions!$E$8:$E$507,"Outflow",Data_Transactions!$C$8:$C$507,">="&(C11-91),Data_Transactions!$C$8:$C$507,"<="&C11)/3,0) -> 0 | N11: =IFERROR(L11/M11,0) -> 0 | O11: =IF(F11=0,"N/A",IF(ABS(F11-(SUMIFS(Data_Transactions!$H$8:$H$507,Data_Transactions!$D$8:$D$507,"Personal",Data_Transactions!$E$8:$E$507,"Inflow",Data_Transactions!$G$8:$G$507,"Active Salary",Data_Transactions!$C$8:$C$507,">="&(B11-3),Data_Transactions!$C$8:$C$507,"<="&(C11+3))))>0.01,"⚠ MISMATCH","✓ OK")) -> N/A
B12: =TODAY()-WEEKDAY(TODAY(),2)+1-49 -> 46125 | C12: =B12+6 -> 46131 | D12: =SUMIFS(Data_Transactions!$H$8:$H$507,Data_Transactions!$D$8:$D$507,"Business",Data_Transactions!$E$8:$E$507,"Inflow",Data_Transactions!$C$8:$C$507,">="&B12,Data_Transactions!$C$8:$C$507,"<="&C12) -> 0 | E12: =SUMIFS(Data_Transactions!$H$8:$H$507,Data_Transactions!$D$8:$D$507,"Business",Data_Transactions!$E$8:$E$507,"Outflow",Data_Transactions!$F$8:$F$507,"Business Operating Expense",Data_Transactions!$C$8:$C$507,">="&B12,Data_Transactions!$C$8:$C$507,"<="&C12) -> 0 | F12: =SUMIFS(Data_Transactions!$H$8:$H$507,Data_Transactions!$D$8:$D$507,"Business",Data_Transactions!$E$8:$E$507,"Outflow",Data_Transactions!$F$8:$F$507,"Owner's Draw",Data_Transactions!$C$8:$C$507,">="&B12,Data_Transactions!$C$8:$C$507,"<="&C12) -> 0 | G12: =D12-E12-F12 -> 0 | H12: =SUMIFS(Data_Transactions!$H$8:$H$507,Data_Transactions!$D$8:$D$507,"Personal",Data_Transactions!$E$8:$E$507,"Inflow",Data_Transactions!$C$8:$C$507,">="&B12,Data_Transactions!$C$8:$C$507,"<="&C12) -> 0 | I12: =SUMIFS(Data_Transactions!$H$8:$H$507,Data_Transactions!$D$8:$D$507,"Personal",Data_Transactions!$E$8:$E$507,"Outflow",Data_Transactions!$F$8:$F$507,"Survival Expenses",Data_Transactions!$C$8:$C$507,">="&B12,Data_Transactions!$C$8:$C$507,"<="&C12) -> 0 | J12: =SUMIFS(Data_Transactions!$H$8:$H$507,Data_Transactions!$D$8:$D$507,"Personal",Data_Transactions!$E$8:$E$507,"Outflow",Data_Transactions!$F$8:$F$507,"Discretionary Expenses",Data_Transactions!$C$8:$C$507,">="&B12,Data_Transactions!$C$8:$C$507,"<="&C12) -> 0 | K12: =H12-I12-J12 -> 0 | L12: =L11+G12 -> 25000 | M12: =IFERROR(SUMIFS(Data_Transactions!$H$8:$H$507,Data_Transactions!$D$8:$D$507,"Business",Data_Transactions!$E$8:$E$507,"Outflow",Data_Transactions!$C$8:$C$507,">="&(C12-91),Data_Transactions!$C$8:$C$507,"<="&C12)/3,0) -> 0 | N12: =IFERROR(L12/M12,0) -> 0 | O12: =IF(F12=0,"N/A",IF(ABS(F12-(SUMIFS(Data_Transactions!$H$8:$H$507,Data_Transactions!$D$8:$D$507,"Personal",Data_Transactions!$E$8:$E$507,"Inflow",Data_Transactions!$G$8:$G$507,"Active Salary",Data_Transactions!$C$8:$C$507,">="&(B12-3),Data_Transactions!$C$8:$C$507,"<="&(C12+3))))>0.01,"⚠ MISMATCH","✓ OK")) -> N/A
B13: =TODAY()-WEEKDAY(TODAY(),2)+1-42 -> 46132 | C13: =B13+6 -> 46138 | D13: =SUMIFS(Data_Transactions!$H$8:$H$507,Data_Transactions!$D$8:$D$507,"Business",Data_Transactions!$E$8:$E$507,"Inflow",Data_Transactions!$C$8:$C$507,">="&B13,Data_Transactions!$C$8:$C$507,"<="&C13) -> 0 | E13: =SUMIFS(Data_Transactions!$H$8:$H$507,Data_Transactions!$D$8:$D$507,"Business",Data_Transactions!$E$8:$E$507,"Outflow",Data_Transactions!$F$8:$F$507,"Business Operating Expense",Data_Transactions!$C$8:$C$507,">="&B13,Data_Transactions!$C$8:$C$507,"<="&C13) -> 0 | F13: =SUMIFS(Data_Transactions!$H$8:$H$507,Data_Transactions!$D$8:$D$507,"Business",Data_Transactions!$E$8:$E$507,"Outflow",Data_Transactions!$F$8:$F$507,"Owner's Draw",Data_Transactions!$C$8:$C$507,">="&B13,Data_Transactions!$C$8:$C$507,"<="&C13) -> 0 | G13: =D13-E13-F13 -> 0 | H13: =SUMIFS(Data_Transactions!$H$8:$H$507,Data_Transactions!$D$8:$D$507,"Personal",Data_Transactions!$E$8:$E$507,"Inflow",Data_Transactions!$C$8:$C$507,">="&B13,Data_Transactions!$C$8:$C$507,"<="&C13) -> 0 | I13: =SUMIFS(Data_Transactions!$H$8:$H$507,Data_Transactions!$D$8:$D$507,"Personal",Data_Transactions!$E$8:$E$507,"Outflow",Data_Transactions!$F$8:$F$507,"Survival Expenses",Data_Transactions!$C$8:$C$507,">="&B13,Data_Transactions!$C$8:$C$507,"<="&C13) -> 0 | J13: =SUMIFS(Data_Transactions!$H$8:$H$507,Data_Transactions!$D$8:$D$507,"Personal",Data_Transactions!$E$8:$E$507,"Outflow",Data_Transactions!$F$8:$F$507,"Discretionary Expenses",Data_Transactions!$C$8:$C$507,">="&B13,Data_Transactions!$C$8:$C$507,"<="&C13) -> 0 | K13: =H13-I13-J13 -> 0 | L13: =L12+G13 -> 25000 | M13: =IFERROR(SUMIFS(Data_Transactions!$H$8:$H$507,Data_Transactions!$D$8:$D$507,"Business",Data_Transactions!$E$8:$E$507,"Outflow",Data_Transactions!$C$8:$C$507,">="&(C13-91),Data_Transactions!$C$8:$C$507,"<="&C13)/3,0) -> 0 | N13: =IFERROR(L13/M13,0) -> 0 | O13: =IF(F13=0,"N/A",IF(ABS(F13-(SUMIFS(Data_Transactions!$H$8:$H$507,Data_Transactions!$D$8:$D$507,"Personal",Data_Transactions!$E$8:$E$507,"Inflow",Data_Transactions!$G$8:$G$507,"Active Salary",Data_Transactions!$C$8:$C$507,">="&(B13-3),Data_Transactions!$C$8:$C$507,"<="&(C13+3))))>0.01,"⚠ MISMATCH","✓ OK")) -> N/A
B14: =TODAY()-WEEKDAY(TODAY(),2)+1-35 -> 46139 | C14: =B14+6 -> 46145 | D14: =SUMIFS(Data_Transactions!$H$8:$H$507,Data_Transactions!$D$8:$D$507,"Business",Data_Transactions!$E$8:$E$507,"Inflow",Data_Transactions!$C$8:$C$507,">="&B14,Data_Transactions!$C$8:$C$507,"<="&C14) -> 0 | E14: =SUMIFS(Data_Transactions!$H$8:$H$507,Data_Transactions!$D$8:$D$507,"Business",Data_Transactions!$E$8:$E$507,"Outflow",Data_Transactions!$F$8:$F$507,"Business Operating Expense",Data_Transactions!$C$8:$C$507,">="&B14,Data_Transactions!$C$8:$C$507,"<="&C14) -> 0 | F14: =SUMIFS(Data_Transactions!$H$8:$H$507,Data_Transactions!$D$8:$D$507,"Business",Data_Transactions!$E$8:$E$507,"Outflow",Data_Transactions!$F$8:$F$507,"Owner's Draw",Data_Transactions!$C$8:$C$507,">="&B14,Data_Transactions!$C$8:$C$507,"<="&C14) -> 0 | G14: =D14-E14-F14 -> 0 | H14: =SUMIFS(Data_Transactions!$H$8:$H$507,Data_Transactions!$D$8:$D$507,"Personal",Data_Transactions!$E$8:$E$507,"Inflow",Data_Transactions!$C$8:$C$507,">="&B14,Data_Transactions!$C$8:$C$507,"<="&C14) -> 0 | I14: =SUMIFS(Data_Transactions!$H$8:$H$507,Data_Transactions!$D$8:$D$507,"Personal",Data_Transactions!$E$8:$E$507,"Outflow",Data_Transactions!$F$8:$F$507,"Survival Expenses",Data_Transactions!$C$8:$C$507,">="&B14,Data_Transactions!$C$8:$C$507,"<="&C14) -> 0 | J14: =SUMIFS(Data_Transactions!$H$8:$H$507,Data_Transactions!$D$8:$D$507,"Personal",Data_Transactions!$E$8:$E$507,"Outflow",Data_Transactions!$F$8:$F$507,"Discretionary Expenses",Data_Transactions!$C$8:$C$507,">="&B14,Data_Transactions!$C$8:$C$507,"<="&C14) -> 0 | K14: =H14-I14-J14 -> 0 | L14: =L13+G14 -> 25000 | M14: =IFERROR(SUMIFS(Data_Transactions!$H$8:$H$507,Data_Transactions!$D$8:$D$507,"Business",Data_Transactions!$E$8:$E$507,"Outflow",Data_Transactions!$C$8:$C$507,">="&(C14-91),Data_Transactions!$C$8:$C$507,"<="&C14)/3,0) -> 0 | N14: =IFERROR(L14/M14,0) -> 0 | O14: =IF(F14=0,"N/A",IF(ABS(F14-(SUMIFS(Data_Transactions!$H$8:$H$507,Data_Transactions!$D$8:$D$507,"Personal",Data_Transactions!$E$8:$E$507,"Inflow",Data_Transactions!$G$8:$G$507,"Active Salary",Data_Transactions!$C$8:$C$507,">="&(B14-3),Data_Transactions!$C$8:$C$507,"<="&(C14+3))))>0.01,"⚠ MISMATCH","✓ OK")) -> N/A
B15: =TODAY()-WEEKDAY(TODAY(),2)+1-28 -> 46146 | C15: =B15+6 -> 46152 | D15: =SUMIFS(Data_Transactions!$H$8:$H$507,Data_Transactions!$D$8:$D$507,"Business",Data_Transactions!$E$8:$E$507,"Inflow",Data_Transactions!$C$8:$C$507,">="&B15,Data_Transactions!$C$8:$C$507,"<="&C15) -> 0 | E15: =SUMIFS(Data_Transactions!$H$8:$H$507,Data_Transactions!$D$8:$D$507,"Business",Data_Transactions!$E$8:$E$507,"Outflow",Data_Transactions!$F$8:$F$507,"Business Operating Expense",Data_Transactions!$C$8:$C$507,">="&B15,Data_Transactions!$C$8:$C$507,"<="&C15) -> 0 | F15: =SUMIFS(Data_Transactions!$H$8:$H$507,Data_Transactions!$D$8:$D$507,"Business",Data_Transactions!$E$8:$E$507,"Outflow",Data_Transactions!$F$8:$F$507,"Owner's Draw",Data_Transactions!$C$8:$C$507,">="&B15,Data_Transactions!$C$8:$C$507,"<="&C15) -> 0 | G15: =D15-E15-F15 -> 0 | H15: =SUMIFS(Data_Transactions!$H$8:$H$507,Data_Transactions!$D$8:$D$507,"Personal",Data_Transactions!$E$8:$E$507,"Inflow",Data_Transactions!$C$8:$C$507,">="&B15,Data_Transactions!$C$8:$C$507,"<="&C15) -> 0 | I15: =SUMIFS(Data_Transactions!$H$8:$H$507,Data_Transactions!$D$8:$D$507,"Personal",Data_Transactions!$E$8:$E$507,"Outflow",Data_Transactions!$F$8:$F$507,"Survival Expenses",Data_Transactions!$C$8:$C$507,">="&B15,Data_Transactions!$C$8:$C$507,"<="&C15) -> 0 | J15: =SUMIFS(Data_Transactions!$H$8:$H$507,Data_Transactions!$D$8:$D$507,"Personal",Data_Transactions!$E$8:$E$507,"Outflow",Data_Transactions!$F$8:$F$507,"Discretionary Expenses",Data_Transactions!$C$8:$C$507,">="&B15,Data_Transactions!$C$8:$C$507,"<="&C15) -> 0 | K15: =H15-I15-J15 -> 0 | L15: =L14+G15 -> 25000 | M15: =IFERROR(SUMIFS(Data_Transactions!$H$8:$H$507,Data_Transactions!$D$8:$D$507,"Business",Data_Transactions!$E$8:$E$507,"Outflow",Data_Transactions!$C$8:$C$507,">="&(C15-91),Data_Transactions!$C$8:$C$507,"<="&C15)/3,0) -> 0 | N15: =IFERROR(L15/M15,0) -> 0 | O15: =IF(F15=0,"N/A",IF(ABS(F15-(SUMIFS(Data_Transactions!$H$8:$H$507,Data_Transactions!$D$8:$D$507,"Personal",Data_Transactions!$E$8:$E$507,"Inflow",Data_Transactions!$G$8:$G$507,"Active Salary",Data_Transactions!$C$8:$C$507,">="&(B15-3),Data_Transactions!$C$8:$C$507,"<="&(C15+3))))>0.01,"⚠ MISMATCH","✓ OK")) -> N/A
B16: =TODAY()-WEEKDAY(TODAY(),2)+1-21 -> 46153 | C16: =B16+6 -> 46159 | D16: =SUMIFS(Data_Transactions!$H$8:$H$507,Data_Transactions!$D$8:$D$507,"Business",Data_Transactions!$E$8:$E$507,"Inflow",Data_Transactions!$C$8:$C$507,">="&B16,Data_Transactions!$C$8:$C$507,"<="&C16) -> 0 | E16: =SUMIFS(Data_Transactions!$H$8:$H$507,Data_Transactions!$D$8:$D$507,"Business",Data_Transactions!$E$8:$E$507,"Outflow",Data_Transactions!$F$8:$F$507,"Business Operating Expense",Data_Transactions!$C$8:$C$507,">="&B16,Data_Transactions!$C$8:$C$507,"<="&C16) -> 0 | F16: =SUMIFS(Data_Transactions!$H$8:$H$507,Data_Transactions!$D$8:$D$507,"Business",Data_Transactions!$E$8:$E$507,"Outflow",Data_Transactions!$F$8:$F$507,"Owner's Draw",Data_Transactions!$C$8:$C$507,">="&B16,Data_Transactions!$C$8:$C$507,"<="&C16) -> 0 | G16: =D16-E16-F16 -> 0 | H16: =SUMIFS(Data_Transactions!$H$8:$H$507,Data_Transactions!$D$8:$D$507,"Personal",Data_Transactions!$E$8:$E$507,"Inflow",Data_Transactions!$C$8:$C$507,">="&B16,Data_Transactions!$C$8:$C$507,"<="&C16) -> 0 | I16: =SUMIFS(Data_Transactions!$H$8:$H$507,Data_Transactions!$D$8:$D$507,"Personal",Data_Transactions!$E$8:$E$507,"Outflow",Data_Transactions!$F$8:$F$507,"Survival Expenses",Data_Transactions!$C$8:$C$507,">="&B16,Data_Transactions!$C$8:$C$507,"<="&C16) -> 0 | J16: =SUMIFS(Data_Transactions!$H$8:$H$507,Data_Transactions!$D$8:$D$507,"Personal",Data_Transactions!$E$8:$E$507,"Outflow",Data_Transactions!$F$8:$F$507,"Discretionary Expenses",Data_Transactions!$C$8:$C$507,">="&B16,Data_Transactions!$C$8:$C$507,"<="&C16) -> 0 | K16: =H16-I16-J16 -> 0 | L16: =L15+G16 -> 25000 | M16: =IFERROR(SUMIFS(Data_Transactions!$H$8:$H$507,Data_Transactions!$D$8:$D$507,"Business",Data_Transactions!$E$8:$E$507,"Outflow",Data_Transactions!$C$8:$C$507,">="&(C16-91),Data_Transactions!$C$8:$C$507,"<="&C16)/3,0) -> 0 | N16: =IFERROR(L16/M16,0) -> 0 | O16: =IF(F16=0,"N/A",IF(ABS(F16-(SUMIFS(Data_Transactions!$H$8:$H$507,Data_Transactions!$D$8:$D$507,"Personal",Data_Transactions!$E$8:$E$507,"Inflow",Data_Transactions!$G$8:$G$507,"Active Salary",Data_Transactions!$C$8:$C$507,">="&(B16-3),Data_Transactions!$C$8:$C$507,"<="&(C16+3))))>0.01,"⚠ MISMATCH","✓ OK")) -> N/A
B17: =TODAY()-WEEKDAY(TODAY(),2)+1-14 -> 46160 | C17: =B17+6 -> 46166 | D17: =SUMIFS(Data_Transactions!$H$8:$H$507,Data_Transactions!$D$8:$D$507,"Business",Data_Transactions!$E$8:$E$507,"Inflow",Data_Transactions!$C$8:$C$507,">="&B17,Data_Transactions!$C$8:$C$507,"<="&C17) -> 0 | E17: =SUMIFS(Data_Transactions!$H$8:$H$507,Data_Transactions!$D$8:$D$507,"Business",Data_Transactions!$E$8:$E$507,"Outflow",Data_Transactions!$F$8:$F$507,"Business Operating Expense",Data_Transactions!$C$8:$C$507,">="&B17,Data_Transactions!$C$8:$C$507,"<="&C17) -> 0 | F17: =SUMIFS(Data_Transactions!$H$8:$H$507,Data_Transactions!$D$8:$D$507,"Business",Data_Transactions!$E$8:$E$507,"Outflow",Data_Transactions!$F$8:$F$507,"Owner's Draw",Data_Transactions!$C$8:$C$507,">="&B17,Data_Transactions!$C$8:$C$507,"<="&C17) -> 0 | G17: =D17-E17-F17 -> 0 | H17: =SUMIFS(Data_Transactions!$H$8:$H$507,Data_Transactions!$D$8:$D$507,"Personal",Data_Transactions!$E$8:$E$507,"Inflow",Data_Transactions!$C$8:$C$507,">="&B17,Data_Transactions!$C$8:$C$507,"<="&C17) -> 0 | I17: =SUMIFS(Data_Transactions!$H$8:$H$507,Data_Transactions!$D$8:$D$507,"Personal",Data_Transactions!$E$8:$E$507,"Outflow",Data_Transactions!$F$8:$F$507,"Survival Expenses",Data_Transactions!$C$8:$C$507,">="&B17,Data_Transactions!$C$8:$C$507,"<="&C17) -> 0 | J17: =SUMIFS(Data_Transactions!$H$8:$H$507,Data_Transactions!$D$8:$D$507,"Personal",Data_Transactions!$E$8:$E$507,"Outflow",Data_Transactions!$F$8:$F$507,"Discretionary Expenses",Data_Transactions!$C$8:$C$507,">="&B17,Data_Transactions!$C$8:$C$507,"<="&C17) -> 0 | K17: =H17-I17-J17 -> 0 | L17: =L16+G17 -> 25000 | M17: =IFERROR(SUMIFS(Data_Transactions!$H$8:$H$507,Data_Transactions!$D$8:$D$507,"Business",Data_Transactions!$E$8:$E$507,"Outflow",Data_Transactions!$C$8:$C$507,">="&(C17-91),Data_Transactions!$C$8:$C$507,"<="&C17)/3,0) -> 0 | N17: =IFERROR(L17/M17,0) -> 0 | O17: =IF(F17=0,"N/A",IF(ABS(F17-(SUMIFS(Data_Transactions!$H$8:$H$507,Data_Transactions!$D$8:$D$507,"Personal",Data_Transactions!$E$8:$E$507,"Inflow",Data_Transactions!$G$8:$G$507,"Active Salary",Data_Transactions!$C$8:$C$507,">="&(B17-3),Data_Transactions!$C$8:$C$507,"<="&(C17+3))))>0.01,"⚠ MISMATCH","✓ OK")) -> N/A
B18: =TODAY()-WEEKDAY(TODAY(),2)+1-7 -> 46167 | C18: =B18+6 -> 46173 | D18: =SUMIFS(Data_Transactions!$H$8:$H$507,Data_Transactions!$D$8:$D$507,"Business",Data_Transactions!$E$8:$E$507,"Inflow",Data_Transactions!$C$8:$C$507,">="&B18,Data_Transactions!$C$8:$C$507,"<="&C18) -> 2500 | E18: =SUMIFS(Data_Transactions!$H$8:$H$507,Data_Transactions!$D$8:$D$507,"Business",Data_Transactions!$E$8:$E$507,"Outflow",Data_Transactions!$F$8:$F$507,"Business Operating Expense",Data_Transactions!$C$8:$C$507,">="&B18,Data_Transactions!$C$8:$C$507,"<="&C18) -> 4000 | F18: =SUMIFS(Data_Transactions!$H$8:$H$507,Data_Transactions!$D$8:$D$507,"Business",Data_Transactions!$E$8:$E$507,"Outflow",Data_Transactions!$F$8:$F$507,"Owner's Draw",Data_Transactions!$C$8:$C$507,">="&B18,Data_Transactions!$C$8:$C$507,"<="&C18) -> 0 | G18: =D18-E18-F18 -> -1500 | H18: =SUMIFS(Data_Transactions!$H$8:$H$507,Data_Transactions!$D$8:$D$507,"Personal",Data_Transactions!$E$8:$E$507,"Inflow",Data_Transactions!$C$8:$C$507,">="&B18,Data_Transactions!$C$8:$C$507,"<="&C18) -> 0 | I18: =SUMIFS(Data_Transactions!$H$8:$H$507,Data_Transactions!$D$8:$D$507,"Personal",Data_Transactions!$E$8:$E$507,"Outflow",Data_Transactions!$F$8:$F$507,"Survival Expenses",Data_Transactions!$C$8:$C$507,">="&B18,Data_Transactions!$C$8:$C$507,"<="&C18) -> 200 | J18: =SUMIFS(Data_Transactions!$H$8:$H$507,Data_Transactions!$D$8:$D$507,"Personal",Data_Transactions!$E$8:$E$507,"Outflow",Data_Transactions!$F$8:$F$507,"Discretionary Expenses",Data_Transactions!$C$8:$C$507,">="&B18,Data_Transactions!$C$8:$C$507,"<="&C18) -> 150 | K18: =H18-I18-J18 -> -350 | L18: =L17+G18 -> 23500 | M18: =IFERROR(SUMIFS(Data_Transactions!$H$8:$H$507,Data_Transactions!$D$8:$D$507,"Business",Data_Transactions!$E$8:$E$507,"Outflow",Data_Transactions!$C$8:$C$507,">="&(C18-91),Data_Transactions!$C$8:$C$507,"<="&C18)/3,0) -> 1333.3333 | N18: =IFERROR(L18/M18,0) -> 17.625 | O18: =IF(F18=0,"N/A",IF(ABS(F18-(SUMIFS(Data_Transactions!$H$8:$H$507,Data_Transactions!$D$8:$D$507,"Personal",Data_Transactions!$E$8:$E$507,"Inflow",Data_Transactions!$G$8:$G$507,"Active Salary",Data_Transactions!$C$8:$C$507,">="&(B18-3),Data_Transactions!$C$8:$C$507,"<="&(C18+3))))>0.01,"⚠ MISMATCH","✓ OK")) -> N/A
B19: =TODAY()-WEEKDAY(TODAY(),2)+1 -> 46174 | C19: =B19+6 -> 46180 | D19: =SUMIFS(Data_Transactions!$H$8:$H$507,Data_Transactions!$D$8:$D$507,"Business",Data_Transactions!$E$8:$E$507,"Inflow",Data_Transactions!$C$8:$C$507,">="&B19,Data_Transactions!$C$8:$C$507,"<="&C19) -> 5000 | E19: =SUMIFS(Data_Transactions!$H$8:$H$507,Data_Transactions!$D$8:$D$507,"Business",Data_Transactions!$E$8:$E$507,"Outflow",Data_Transactions!$F$8:$F$507,"Business Operating Expense",Data_Transactions!$C$8:$C$507,">="&B19,Data_Transactions!$C$8:$C$507,"<="&C19) -> 950 | F19: =SUMIFS(Data_Transactions!$H$8:$H$507,Data_Transactions!$D$8:$D$507,"Business",Data_Transactions!$E$8:$E$507,"Outflow",Data_Transactions!$F$8:$F$507,"Owner's Draw",Data_Transactions!$C$8:$C$507,">="&B19,Data_Transactions!$C$8:$C$507,"<="&C19) -> 3000 | G19: =D19-E19-F19 -> 1050 | H19: =SUMIFS(Data_Transactions!$H$8:$H$507,Data_Transactions!$D$8:$D$507,"Personal",Data_Transactions!$E$8:$E$507,"Inflow",Data_Transactions!$C$8:$C$507,">="&B19,Data_Transactions!$C$8:$C$507,"<="&C19) -> 3000 | I19: =SUMIFS(Data_Transactions!$H$8:$H$507,Data_Transactions!$D$8:$D$507,"Personal",Data_Transactions!$E$8:$E$507,"Outflow",Data_Transactions!$F$8:$F$507,"Survival Expenses",Data_Transactions!$C$8:$C$507,">="&B19,Data_Transactions!$C$8:$C$507,"<="&C19) -> 1500 | J19: =SUMIFS(Data_Transactions!$H$8:$H$507,Data_Transactions!$D$8:$D$507,"Personal",Data_Transactions!$E$8:$E$507,"Outflow",Data_Transactions!$F$8:$F$507,"Discretionary Expenses",Data_Transactions!$C$8:$C$507,">="&B19,Data_Transactions!$C$8:$C$507,"<="&C19) -> 130 | K19: =H19-I19-J19 -> 1370 | L19: =L18+G19 -> 24550 | M19: =IFERROR(SUMIFS(Data_Transactions!$H$8:$H$507,Data_Transactions!$D$8:$D$507,"Business",Data_Transactions!$E$8:$E$507,"Outflow",Data_Transactions!$C$8:$C$507,">="&(C19-91),Data_Transactions!$C$8:$C$507,"<="&C19)/3,0) -> 2650 | N19: =IFERROR(L19/M19,0) -> 9.2641509 | O19: =IF(F19=0,"N/A",IF(ABS(F19-(SUMIFS(Data_Transactions!$H$8:$H$507,Data_Transactions!$D$8:$D$507,"Personal",Data_Transactions!$E$8:$E$507,"Inflow",Data_Transactions!$G$8:$G$507,"Active Salary",Data_Transactions!$C$8:$C$507,">="&(B19-3),Data_Transactions!$C$8:$C$507,"<="&(C19+3))))>0.01,"⚠ MISMATCH","✓ OK")) -> ✓ OK
B21: ▶ GREEN = inflow | C21: ▶ RED = outflow | D21: ▶ AMBER = draw | E21: ▶ BLUE = runway | F21: ▶ ROW 19 = CURRENT WEEK

Sheet Dashboard_Pulse
B2: ⚙ CONFIG SETUP | F2: 📋 LEDGER | J2: ∑ ENGINE | N2: ◉ DASHBOARD
B5: ◉ PULSE DASHBOARD | H5: WEEKLY PARTNER CHECK-IN
B7: BUSINESS HEALTH | I7: PERSONAL BUDGET PACING
B9: TODAY's DATE | I9: WEEKLY DISCRETIONARY LIMIT
B10: =TEXT(TODAY(),"YYYY-MM-DD") -> 2026-06-06 | I10: =IFERROR(Config_Setup!$C$49,0) -> 300
B12: BUSINESS RUNWAY (MONTHS) | I12: WEEKLY SPENT TO DATE
B13: =IFERROR(Calc_Engine!$N$19,0) -> 9.2641509 | I13: =IFERROR(SUMIFS(Data_Transactions!$H$8:$H$507,Data_Transactions!$D$8:$D$507,"Personal",Data_Transactions!$E$8:$E$507,"Outflow",Data_Transactions!$F$8:$F$507,"Discretionary Expenses",Data_Transactions!$C$8:$C$507,">="&Calc_Engine!$B$19,Data_Transactions!$C$8:$C$507,"<="&Calc_Engine!$C$19),0) -> 130
B15: RUNWAY ALERT STATUS | I15: BUDGET VARIANCE (REMAINING)
B16: =IF(IFERROR(Calc_Engine!$N$19,0)>=3,"SAFE",IF(IFERROR(Calc_Engine!$N$19,0)>=1.5,"WARNING","CRITICAL")) -> SAFE | I16: =I10-I13 -> 170
B18: WEEKLY BIZ NET CASH FLOW | I18: WEEKLY PULSE RESULT
B19: =IFERROR(Calc_Engine!$G$19,0) -> 1050 | I19: =IF(AND(IFERROR(Calc_Engine!$N$19,0)>=3,IFERROR(I13/I10,1)<0.85),"GREEN LIGHT",IF(OR(AND(IFERROR(Calc_Engine!$N$19,0)>=1.5,IFERROR(Calc_Engine!$N$19,0)<3),AND(IFERROR(I13/I10,1)>=0.85,IFERROR(I13/I10,1)<=1)),"YELLOW LIGHT","RED LIGHT")) -> GREEN LIGHT
B21: BUSINESS CASH POSITION | I21: PERSONAL NET CASH FLOW
B22: =IFERROR(Calc_Engine!$L$19,0) -> 24550 | I22: =IFERROR(Calc_Engine!$K$19,0) -> 1370
B24: EST. MONTHLY BURN RATE | I24: TOTAL PENDING ALERTS
B25: =IFERROR(Calc_Engine!$M$19,0) -> 2650 | I25: =COUNTIF(Data_Transactions!$J$8:$J$507,"Pending") -> 1
B27: ⚑ PENDING ITEMS TO RECONCILE
B28: Items below require owner verification. Target: Pending Count = 0 at end of each weekly check-in.
B29: Tx ID | C29: Date | D29: Entity | E29: Type | F29: Category | G29: Sub-Category | H29: Amount | I29: Description | J29: Status | K29: Flag | L29: Admin Notes
B30: [ ↓ Excel 365 FILTER function — auto-spills rows when file is opened in Excel 365 ]
B31: =IFERROR(filter(Data_Transactions!$B$8:$L$507,Data_Transactions!$J$8:$J$507="Pending","✓ No pending items — ledger is fully reconciled"),"FILTER function requires Excel 365 or Excel 2019+") -> FILTER function requires Excel 365 or Excel 2019+
